[2025-09-29 10:38:37.066] evaluator-0 started
[2025-09-29 10:38:37.067] Initializing model
[2025-09-29 10:38:37.086] 
===================== Exception caught =====================
Traceback (most recent call last):
  File "/Users/eithan/Library/Caches/pypoetry/virtualenvs/connect-four-ai-6X4jT3Yc-py3.12/lib/python3.12/site-packages/open_spiel/python/algorithms/alpha_zero/alpha_zero.py", line 171, in _watcher
    return fn(config=config, logger=logger, **kwargs)
           ^^^^^^^^^^^^^^^^^^^^^^^^^^^^^^^^^^^^^^^^^^
  File "/Users/eithan/Library/Caches/pypoetry/virtualenvs/connect-four-ai-6X4jT3Yc-py3.12/lib/python3.12/site-packages/open_spiel/python/algorithms/alpha_zero/alpha_zero.py", line 289, in evaluator
    model = _init_model_from_config(config)
            ^^^^^^^^^^^^^^^^^^^^^^^^^^^^^^^
  File "/Users/eithan/Library/Caches/pypoetry/virtualenvs/connect-four-ai-6X4jT3Yc-py3.12/lib/python3.12/site-packages/open_spiel/python/algorithms/alpha_zero/alpha_zero.py", line 148, in _init_model_from_config
    return model_lib.Model.build_model(
           ^^^^^^^^^^^^^^^^^^^^^^^^^^^^
  File "/Users/eithan/Library/Caches/pypoetry/virtualenvs/connect-four-ai-6X4jT3Yc-py3.12/lib/python3.12/site-packages/open_spiel/python/algorithms/alpha_zero/model.py", line 183, in build_model
    cls._define_graph(model_type, input_shape, output_size, nn_width,
  File "/Users/eithan/Library/Caches/pypoetry/virtualenvs/connect-four-ai-6X4jT3Yc-py3.12/lib/python3.12/site-packages/open_spiel/python/algorithms/alpha_zero/model.py", line 251, in _define_graph
    torso = cascade(observations, [
            ^^^^^^^^^^^^^^^^^^^^^^^
  File "/Users/eithan/Library/Caches/pypoetry/virtualenvs/connect-four-ai-6X4jT3Yc-py3.12/lib/python3.12/site-packages/open_spiel/python/algorithms/alpha_zero/model.py", line 36, in cascade
    x = fn(x)
        ^^^^^
  File "/Users/eithan/Library/Caches/pypoetry/virtualenvs/connect-four-ai-6X4jT3Yc-py3.12/lib/python3.12/site-packages/open_spiel/python/algorithms/alpha_zero/model.py", line 58, in batch_norm_layer
    applied = bn(x, training)
              ^^^^^^^^^^^^^^^
  File "/Users/eithan/Library/Caches/pypoetry/virtualenvs/connect-four-ai-6X4jT3Yc-py3.12/lib/python3.12/site-packages/keras/src/utils/traceback_utils.py", line 122, in error_handler
    raise e.with_traceback(filtered_tb) from None
  File "/Users/eithan/Library/Caches/pypoetry/virtualenvs/connect-four-ai-6X4jT3Yc-py3.12/lib/python3.12/site-packages/tensorflow/python/framework/tensor_shape.py", line 1440, in as_list
    raise ValueError("as_list() is not defined on an unknown TensorShape.")
ValueError: as_list() is not defined on an unknown TensorShape.

============================================================
[2025-09-29 10:38:37.086] evaluator-0 exiting
